test_01_create_karyawan_with_valid_photo (__main__.KaryawanPhotoTestSuite)
Test creating karyawan with valid photo ... FAIL
test_02_upload_photo_to_existing_karyawan (__main__.KaryawanPhotoTestSuite)
Test uploading photo to existing karyawan ... ERROR
test_03_delete_photo_from_karyawan (__main__.KaryawanPhotoTestSuite)
Test deleting photo from karyawan ... FAIL
test_04_reject_invalid_file_types (__main__.KaryawanPhotoTestSuite)
Test rejection of invalid file types ... test_05_reject_large_files (__main__.KaryawanPhotoTestSuite)
Test rejection of files over size limit ... ok
test_06_validate_karyawan_data (__main__.KaryawanPhotoTestSuite)
Test validation of karyawan data fields ... ok
test_07_missing_photo_field (__main__.KaryawanPhotoTestSuite)
Test creating karyawan with photo endpoint but no photo file ... FAIL
test_08_nonexistent_karyawan_photo_ops (__main__.KaryawanPhotoTestSuite)
Test photo operations on non-existent karyawan ... ok
test_09_empty_file_upload (__main__.KaryawanPhotoTestSuite)
Test uploading empty file ... FAIL
test_10_supported_image_formats (__main__.KaryawanPhotoTestSuite)
Test all supported image formats ... test_11_get_karyawan_with_photo_info (__main__.KaryawanPhotoTestSuite)
Test retrieving karyawan data with photo information ... FAIL
test_12_photo_file_accessibility (__main__.KaryawanPhotoTestSuite)
Test that uploaded photos are accessible via HTTP ... FAIL
test_13_concurrent_photo_uploads (__main__.KaryawanPhotoTestSuite)
Test concurrent photo uploads ... FAIL

======================================================================
ERROR: test_02_upload_photo_to_existing_karyawan (__main__.KaryawanPhotoTestSuite)
Test uploading photo to existing karyawan
----------------------------------------------------------------------
Traceback (most recent call last):
  File "C:\Users\jauha\my-axum-app\comprehensive_photo_tests.py", line 191, in test_02_upload_photo_to_existing_karyawan
    karyawan_id = result['data']['id']
TypeError: 'NoneType' object is not subscriptable

======================================================================
FAIL: test_01_create_karyawan_with_valid_photo (__main__.KaryawanPhotoTestSuite)
Test creating karyawan with valid photo
----------------------------------------------------------------------
Traceback (most recent call last):
  File "C:\Users\jauha\my-axum-app\comprehensive_photo_tests.py", line 153, in test_01_create_karyawan_with_valid_photo
    self.assertTrue(result['success'])
AssertionError: False is not true

During handling of the above exception, another exception occurred:

Traceback (most recent call last):
  File "C:\Users\jauha\my-axum-app\comprehensive_photo_tests.py", line 172, in test_01_create_karyawan_with_valid_photo
    self.fail(f"Failed to create karyawan with photo: {str(e)}")
AssertionError: Failed to create karyawan with photo: False is not true

======================================================================
FAIL: test_03_delete_photo_from_karyawan (__main__.KaryawanPhotoTestSuite)
Test deleting photo from karyawan
----------------------------------------------------------------------
Traceback (most recent call last):
  File "C:\Users\jauha\my-axum-app\comprehensive_photo_tests.py", line 153, in test_01_create_karyawan_with_valid_photo
    self.assertTrue(result['success'])
AssertionError: False is not true

During handling of the above exception, another exception occurred:

Traceback (most recent call last):
  File "C:\Users\jauha\my-axum-app\comprehensive_photo_tests.py", line 227, in test_03_delete_photo_from_karyawan
    karyawan_id = self.test_01_create_karyawan_with_valid_photo()
  File "C:\Users\jauha\my-axum-app\comprehensive_photo_tests.py", line 172, in test_01_create_karyawan_with_valid_photo
    self.fail(f"Failed to create karyawan with photo: {str(e)}")
AssertionError: Failed to create karyawan with photo: False is not true

======================================================================
FAIL: test_04_reject_invalid_file_types (__main__.KaryawanPhotoTestSuite) (file_type='text/plain')
Test rejection of invalid file types
----------------------------------------------------------------------
Traceback (most recent call last):
  File "C:\Users\jauha\my-axum-app\comprehensive_photo_tests.py", line 290, in test_04_reject_invalid_file_types
    self.assertIn('Invalid file type', result['message'])
AssertionError: 'Invalid file type' not found in 'Failed to upload photo'

During handling of the above exception, another exception occurred:

Traceback (most recent call last):
  File "C:\Users\jauha\my-axum-app\comprehensive_photo_tests.py", line 295, in test_04_reject_invalid_file_types
    self.fail(f"Error testing {content_type}: {str(e)}")
AssertionError: Error testing text/plain: 'Invalid file type' not found in 'Failed to upload photo'

======================================================================
FAIL: test_04_reject_invalid_file_types (__main__.KaryawanPhotoTestSuite) (file_type='application/pdf')
Test rejection of invalid file types
----------------------------------------------------------------------
Traceback (most recent call last):
  File "C:\Users\jauha\my-axum-app\comprehensive_photo_tests.py", line 290, in test_04_reject_invalid_file_types
    self.assertIn('Invalid file type', result['message'])
AssertionError: 'Invalid file type' not found in 'Failed to upload photo'

During handling of the above exception, another exception occurred:

Traceback (most recent call last):
  File "C:\Users\jauha\my-axum-app\comprehensive_photo_tests.py", line 295, in test_04_reject_invalid_file_types
    self.fail(f"Error testing {content_type}: {str(e)}")
AssertionError: Error testing application/pdf: 'Invalid file type' not found in 'Failed to upload photo'

======================================================================
FAIL: test_04_reject_invalid_file_types (__main__.KaryawanPhotoTestSuite) (file_type='application/octet-stream')
Test rejection of invalid file types
----------------------------------------------------------------------
Traceback (most recent call last):
  File "C:\Users\jauha\my-axum-app\comprehensive_photo_tests.py", line 290, in test_04_reject_invalid_file_types
    self.assertIn('Invalid file type', result['message'])
AssertionError: 'Invalid file type' not found in 'Failed to upload photo'

During handling of the above exception, another exception occurred:

Traceback (most recent call last):
  File "C:\Users\jauha\my-axum-app\comprehensive_photo_tests.py", line 295, in test_04_reject_invalid_file_types
    self.fail(f"Error testing {content_type}: {str(e)}")
AssertionError: Error testing application/octet-stream: 'Invalid file type' not found in 'Failed to upload photo'

======================================================================
FAIL: test_07_missing_photo_field (__main__.KaryawanPhotoTestSuite)
Test creating karyawan with photo endpoint but no photo file
----------------------------------------------------------------------
Traceback (most recent call last):
  File "C:\Users\jauha\my-axum-app\comprehensive_photo_tests.py", line 427, in test_07_missing_photo_field
    self.assertEqual(response.status_code, 200)
AssertionError: 400 != 200

======================================================================
FAIL: test_09_empty_file_upload (__main__.KaryawanPhotoTestSuite)
Test uploading empty file
----------------------------------------------------------------------
Traceback (most recent call last):
  File "C:\Users\jauha\my-axum-app\comprehensive_photo_tests.py", line 504, in test_09_empty_file_upload
    self.assertIn('empty', result['message'].lower())
AssertionError: 'empty' not found in 'failed to upload photo'

During handling of the above exception, another exception occurred:

Traceback (most recent call last):
  File "C:\Users\jauha\my-axum-app\comprehensive_photo_tests.py", line 509, in test_09_empty_file_upload
    self.fail(f"Error testing empty file: {str(e)}")
AssertionError: Error testing empty file: 'empty' not found in 'failed to upload photo'

======================================================================
FAIL: test_10_supported_image_formats (__main__.KaryawanPhotoTestSuite) (format='JPEG')
Test all supported image formats
----------------------------------------------------------------------
Traceback (most recent call last):
  File "C:\Users\jauha\my-axum-app\comprehensive_photo_tests.py", line 550, in test_10_supported_image_formats
    self.assertTrue(result['success'])
AssertionError: False is not true

During handling of the above exception, another exception occurred:

Traceback (most recent call last):
  File "C:\Users\jauha\my-axum-app\comprehensive_photo_tests.py", line 563, in test_10_supported_image_formats
    self.fail(f"Error testing {format_name}: {str(e)}")
AssertionError: Error testing JPEG: False is not true

======================================================================
FAIL: test_10_supported_image_formats (__main__.KaryawanPhotoTestSuite) (format='PNG')
Test all supported image formats
----------------------------------------------------------------------
Traceback (most recent call last):
  File "C:\Users\jauha\my-axum-app\comprehensive_photo_tests.py", line 550, in test_10_supported_image_formats
    self.assertTrue(result['success'])
AssertionError: False is not true

During handling of the above exception, another exception occurred:

Traceback (most recent call last):
  File "C:\Users\jauha\my-axum-app\comprehensive_photo_tests.py", line 563, in test_10_supported_image_formats
    self.fail(f"Error testing {format_name}: {str(e)}")
AssertionError: Error testing PNG: False is not true

======================================================================
FAIL: test_11_get_karyawan_with_photo_info (__main__.KaryawanPhotoTestSuite)
Test retrieving karyawan data with photo information
----------------------------------------------------------------------
Traceback (most recent call last):
  File "C:\Users\jauha\my-axum-app\comprehensive_photo_tests.py", line 153, in test_01_create_karyawan_with_valid_photo
    self.assertTrue(result['success'])
AssertionError: False is not true

During handling of the above exception, another exception occurred:

Traceback (most recent call last):
  File "C:\Users\jauha\my-axum-app\comprehensive_photo_tests.py", line 574, in test_11_get_karyawan_with_photo_info
    karyawan_id = self.test_01_create_karyawan_with_valid_photo()
  File "C:\Users\jauha\my-axum-app\comprehensive_photo_tests.py", line 172, in test_01_create_karyawan_with_valid_photo
    self.fail(f"Failed to create karyawan with photo: {str(e)}")
AssertionError: Failed to create karyawan with photo: False is not true

======================================================================
FAIL: test_12_photo_file_accessibility (__main__.KaryawanPhotoTestSuite)
Test that uploaded photos are accessible via HTTP
----------------------------------------------------------------------
Traceback (most recent call last):
  File "C:\Users\jauha\my-axum-app\comprehensive_photo_tests.py", line 153, in test_01_create_karyawan_with_valid_photo
    self.assertTrue(result['success'])
AssertionError: False is not true

During handling of the above exception, another exception occurred:

Traceback (most recent call last):
  File "C:\Users\jauha\my-axum-app\comprehensive_photo_tests.py", line 607, in test_12_photo_file_accessibility
    karyawan_id = self.test_01_create_karyawan_with_valid_photo()
  File "C:\Users\jauha\my-axum-app\comprehensive_photo_tests.py", line 172, in test_01_create_karyawan_with_valid_photo
    self.fail(f"Failed to create karyawan with photo: {str(e)}")
AssertionError: Failed to create karyawan with photo: False is not true

======================================================================
FAIL: test_13_concurrent_photo_uploads (__main__.KaryawanPhotoTestSuite)
Test concurrent photo uploads
----------------------------------------------------------------------
Traceback (most recent call last):
  File "C:\Users\jauha\my-axum-app\comprehensive_photo_tests.py", line 700, in test_13_concurrent_photo_uploads
    self.assertGreater(len(results), 0, "No concurrent uploads succeeded")
AssertionError: 0 not greater than 0 : No concurrent uploads succeeded

----------------------------------------------------------------------
Ran 13 tests in 43.843s

FAILED (failures=12, errors=1)
